Workbook

Sheet Read Me
B1: Chipotle Mexican Grill (CMG): Valuation Model & Stock Pitch
B3: WHAT THIS IS
B4: A formula-linked 3-statement model (income statement, balance sheet, cash flow) for Chipotle, with a DCF and a comparable-companies analysis. History (FY2023-FY2025) comes from Chipotle's reported financials; FY2026E-FY2030E are projected from the assumptions you can edit.
B6: HOW TO USE IT
B7: • The inputs are on the Assumptions tab; change those values. Every other tab is driven by formulas.
B8: • Start on the Assumptions tab: unit growth, comparable sales, and cost margins drive the whole model.
B9: • The DCF tab builds WACC, discounts unlevered free cash flow, and shows two terminal-value methods plus sensitivity tables.
B10: • The Balance Sheet tab has a 'Balance check' row (row 27) that must read 0 in every year, which proves the statements tie together.
B12: TABS
B13: Assumptions · Income Statement · Balance Sheet · Cash Flow · DCF · Comps
B15: VALUATION SUMMARY (auto-calculated)
B16: Current price (Jun 22, 2026): | D16: =DCF!C44 -> 30.54
B17: DCF average implied price: | D17: =DCF!C49 -> 35.578413
B18: DCF upside/(downside): | D18: =DCF!C50 -> 0.16497752
B19: Comps (EV/EBITDA) implied price: | D19: =Comps!C22 -> 39.559453
B20: Blended target (DCF + comps avg): | D20: =AVERAGE(DCF!C49,Comps!C22) -> 37.568933
B21: Blended upside/(downside): | D21: =D20/DCF!C44-1 -> 0.23015499
B23: KEY ASSUMPTIONS (base case)
B24: • Unit growth: about 320-410 net new restaurants a year, toward the company's long-term ~7,000 N.A. target (~8% unit growth).
B25: • Comparable sales: recover from -1.7% (FY2025) to +1.5%, then +3.0-3.5% as traffic normalizes and menu changes and price contribute.
B26: • Restaurant-level margin: ~25.4% (FY2025) recovering toward ~27% as sales improve; operating margin to ~18%.
B27: • WACC ~9.4% (beta 0.98, ERP 5.0%, risk-free 4.48%); terminal growth 3.0%; exit EV/EBITDA 18.0x. No funded debt (leases treated as operating).
B29: TALKING POINTS (how to defend it)
B30: • Thesis: CMG earns high returns (ROIC over 20%) and has fallen ~40% over the past year on soft traffic. At ~19x EV/EBITDA and ~26x forward earnings it trades below fast-casual peers (CAVA ~72x, WING ~25x) despite greater scale and stronger unit economics.
B31: • Value drivers: unit growth (room to reach ~7,000 N.A. stores), margin recovery as sales improve, and heavy buybacks lowering the share count about 2-3% a year.
B32: • Why leases are treated as operating: CMG has no traditional borrowings, so its reported 'debt' is capitalized operating leases. Occupancy (rent) is already in the P&L, so FCF is after rent and net debt excludes lease liabilities. This keeps the DCF consistent.
B33: • Key risks: persistent traffic weakness, wage/food (beef, chicken) inflation and tariffs, cannibalization as the base grows, and a premium multiple that leaves little room for error.
B35: DATA SOURCES
B36: • Chipotle Q4 and FY2025 results (Feb 3, 2026): newsroom.chipotle.com / prnewswire, for income statement detail, comps, unit counts, restaurant-level margin.
... B39: • U.S. 10-Year Treasury yield 4.48% (Jun 23, 2026), tradingeconomics / Federal Reserve H.15.

Sheet Assumptions
A1: Chipotle Mexican Grill (CMG): Assumptions & Drivers
A2: Inputs live on this tab; change the values. ($ in millions unless noted; fiscal year = calendar year)
A4: Driver | C4: FY2023 | D4: FY2024 | E4: FY2025 | F4: FY2026E | G4: FY2027E | H4: FY2028E | I4: FY2029E | J4: FY2030E
A5: OPERATING DRIVERS
A6: Company-operated restaurants (end of period) | C6: 3437 | D6: 3726 | E6: 4042 | F6: =E6+F7 -> 4362 | G6: =F6+G7 -> 4707 | H6: =G6+H7 -> 5077 | I6: =H6+I7 -> 5467 | J6: =I6+J7 -> 5877
A7: Net new units added | D7: =D6-C6 -> 289 | E7: =E6-D6 -> 316 | F7: 320 | G7: 345 | H7: 370 | I7: 390 | J7: 410
A8: % unit growth | D8: =D6/C6-1 -> 0.084084958 | E8: =E6/D6-1 -> 0.084809447 | F8: =F6/E6-1 -> 0.079168728 | G8: =G6/F6-1 -> 0.07909216 | H8: =H6/G6-1 -> 0.078606331 | I8: =I6/H6-1 -> 0.076817018 | J8: =J6/I6-1 -> 0.074995427
A9: Average units (period) | D9: =(C6+D6)/2 -> 3581.5 | E9: =(D6+E6)/2 -> 3884 | F9: =(E6+F6)/2 -> 4202 | G9: =(F6+G6)/2 -> 4534.5 | H9: =(G6+H6)/2 -> 4892 | I9: =(H6+I6)/2 -> 5272 | J9: =(I6+J6)/2 -> 5672
A10: Sales per average unit ($mm) | D10: ='Income Statement'!D8/D9 -> 3.1589837 | E10: ='Income Statement'!E8/E9 -> 3.0704428 | F10: =E10*(1+F11) -> 3.1164995 | G10: =F10*(1+G11) -> 3.225577 | H10: =G10*(1+H11) -> 3.3384722 | I10: =H10*(1+I11) -> 3.4386263 | J10: =I10*(1+J11) -> 3.5417851
A11: Comparable restaurant sales growth % | C11: 0.079 | D11: 0.074 | E11: -0.017 | F11: 0.015 | G11: 0.035 | H11: 0.035 | I11: 0.03 | J11: 0.03
A13: MARGIN & COST DRIVERS (% of revenue)
A14: Food, beverage & packaging | C14: 0.295 | D14: 0.298 | E14: 0.296 | F14: 0.296 | G14: 0.296 | H14: 0.295 | I14: 0.295 | J14: 0.295
A15: Labor | C15: 0.247 | D15: 0.247 | E15: 0.251 | F15: 0.25 | G15: 0.247 | H15: 0.245 | I15: 0.244 | J15: 0.243
A16: Occupancy | C16: 0.053 | D16: 0.05 | E16: 0.052 | F16: 0.052 | G16: 0.051 | H16: 0.051 | I16: 0.05 | J16: 0.05
A17: Other operating costs | C17: 0.143 | D17: 0.139 | E17: 0.147 | F17: 0.145 | G17: 0.144 | H17: 0.143 | I17: 0.143 | J17: 0.142
A18: Restaurant-level margin % (=1 − above) | C18: =1-C14-C15-C16-C17 -> 0.262 | D18: =1-D14-D15-D16-D17 -> 0.266 | E18: =1-E14-E15-E16-E17 -> 0.254 | F18: =1-F14-F15-F16-F17 -> 0.257 | G18: =1-G14-G15-G16-G17 -> 0.262 | H18: =1-H14-H15-H16-H17 -> 0.266 | I18: =1-I14-I15-I16-I17 -> 0.268 | J18: =1-J14-J15-J16-J17 -> 0.27
A19: General & administrative | C19: 0.064 | D19: 0.062 | E19: 0.055 | F19: 0.054 | G19: 0.053 | H19: 0.052 | I19: 0.051 | J19: 0.051
A20: Depreciation & amortization | C20: 0.032 | D20: 0.03 | E20: 0.03 | F20: 0.031 | G20: 0.031 | H20: 0.031 | I20: 0.031 | J20: 0.031
A21: Pre-opening costs | C21: 0.005 | D21: 0.004 | E21: 0.004 | F21: 0.004 | G21: 0.004 | H21: 0.004 | I21: 0.004 | J21: 0.004
A22: Impairment, closure & other | C22: 0.003 | D22: 0.002 | E22: 0.002 | F22: 0.002 | G22: 0.002 | H22: 0.002 | I22: 0.002 | J22: 0.002
A23: Operating margin % (implied) | C23: =C18-C19-C20-C21-C22 -> 0.158 | D23: =D18-D19-D20-D21-D22 -> 0.168 | E23: =E18-E19-E20-E21-E22 -> 0.163 | F23: =F18-F19-F20-F21-F22 -> 0.166 | G23: =G18-G19-G20-G21-G22 -> 0.172 | H23: =H18-H19-H20-H21-H22 -> 0.177 | I23: =I18-I19-I20-I21-I22 -> 0.18 | J23: =J18-J19-J20-J21-J22 -> 0.182
A25: OTHER DRIVERS
A26: Interest & other income (% of beg. cash+investments) | F26: 0.035 | G26: 0.035 | H26: 0.035 | I26: 0.035 | J26: 0.035
A27: Effective tax rate | C27: 0.242 | D27: 0.237 | E27: 0.236 | F27: 0.24 | G27: 0.24 | H27: 0.24 | I27: 0.24 | J27: 0.24
A28: Capital expenditures (% of revenue) | C28: 0.0568 | D28: 0.0525 | E28: 0.0559 | F28: 0.056 | G28: 0.056 | H28: 0.055 | I28: 0.055 | J28: 0.054
A29: Stock-based compensation ($mm) | C29: 124 | D29: 131.7 | E29: 119.5 | F29: 120 | G29: 125 | H29: 130 | I29: 135 | J29: 140
A30: Buyback payout (% of free cash flow) | F30: 0.8 | G30: 0.8 | H30: 0.8 | I30: 0.8 | J30: 0.8
A31: Assumed repurchase price ($/share) | F31: 30.54 | G31: 30.54 | H31: 30.54 | I31: 30.54 | J31: 30.54
A33: WORKING CAPITAL & BALANCE SHEET (% of revenue)
A34: Accounts receivable | F34: 0.0131 | G34: 0.0131 | H34: 0.0131 | I34: 0.0131 | J34: 0.0131 | L34: WC ratios held at FY2025 actual levels.
A35: Inventory | F35: 0.00415 | G35: 0.00415 | H35: 0.00415 | I35: 0.00415 | J35: 0.00415
A36: Prepaid & other current assets | F36: 0.0178 | G36: 0.0178 | H36: 0.0178 | I36: 0.0178 | J36: 0.0178
A37: Accounts payable | F37: 0.0178 | G37: 0.0178 | H37: 0.0178 | I37: 0.0178 | J37: 0.0178
A38: Accrued & other current liabilities | F38: 0.0363 | G38: 0.0363 | H38: 0.0363 | I38: 0.0363 | J38: 0.0363
A39: Unearned revenue (loyalty/gift cards) | F39: 0.0202 | G39: 0.0202 | H39: 0.0202 | I39: 0.0202 | J39: 0.0202
A40: Current portion of lease liabilities | F40: 0.0254 | G40: 0.0254 | H40: 0.0254 | I40: 0.0254 | J40: 0.0254
A41: Long-term lease liabilities | F41: 0.4002 | G41: 0.4002 | H41: 0.4002 | I41: 0.4002 | J41: 0.4002

Sheet Income Statement
A1: Chipotle Mexican Grill: Consolidated Income Statement
A2: $ in millions except per share; FY2023-25 reported, FY2026E-30E projected
C4: FY2023 | D4: FY2024 | E4: FY2025 | F4: FY2026E | G4: FY2027E | H4: FY2028E | I4: FY2029E | J4: FY2030E
A5: Company-operated restaurants (EOP) | C5: =Assumptions!C6 -> 3437 | D5: =Assumptions!D6 -> 3726 | E5: =Assumptions!E6 -> 4042 | F5: =Assumptions!F6 -> 4362 | G5: =Assumptions!G6 -> 4707 | H5: =Assumptions!H6 -> 5077 | I5: =Assumptions!I6 -> 5467 | J5: =Assumptions!J6 -> 5877
A6: Comparable restaurant sales growth % | C6: =Assumptions!C11 -> 0.079 | D6: =Assumptions!D11 -> 0.074 | E6: =Assumptions!E11 -> -0.017 | F6: =Assumptions!F11 -> 0.015 | G6: =Assumptions!G11 -> 0.035 | H6: =Assumptions!H11 -> 0.035 | I6: =Assumptions!I11 -> 0.03 | J6: =Assumptions!J11 -> 0.03
A8: Total revenue | C8: 9871.7 | D8: 11313.9 | E8: 11925.6 | F8: =Assumptions!F9*Assumptions!F10 -> 13095.531 | G8: =Assumptions!G9*Assumptions!G10 -> 14626.379 | H8: =Assumptions!H9*Assumptions!H10 -> 16331.806 | I8: =Assumptions!I9*Assumptions!I10 -> 18128.438 | J8: =Assumptions!J9*Assumptions!J10 -> 20089.005
A9: % growth | D9: =D8/C8-1 -> 0.14609439 | E9: =E8/D8-1 -> 0.054066237 | F9: =F8/E8-1 -> 0.098102472 | G9: =G8/F8-1 -> 0.1168985 | H9: =H8/G8-1 -> 0.1165994 | I9: =I8/H8-1 -> 0.11000818 | J9: =J8/I8-1 -> 0.10814871
A10: Food, beverage & packaging | C10: 2912.1 | D10: 3374.5 | E10: 3527 | F10: =Assumptions!F14*F8 -> 3876.2771 | G10: =Assumptions!G14*G8 -> 4329.4081 | H10: =Assumptions!H14*H8 -> 4817.8827 | I10: =Assumptions!I14*I8 -> 5347.8892 | J10: =Assumptions!J14*J8 -> 5926.2565
A11: Labor | C11: 2438.3 | D11: 2789.8 | E11: 2991.7 | F11: =Assumptions!F15*F8 -> 3273.8827 | G11: =Assumptions!G15*G8 -> 3612.7156 | H11: =Assumptions!H15*H8 -> 4001.2924 | I11: =Assumptions!I15*I8 -> 4423.3389 | J11: =Assumptions!J15*J8 -> 4881.6283
A12: Occupancy | C12: 523.2 | D12: 563.4 | E12: 624.9 | F12: =Assumptions!F16*F8 -> 680.9676 | G12: =Assumptions!G16*G8 -> 745.94532 | H12: =Assumptions!H16*H8 -> 832.9221 | I12: =Assumptions!I16*I8 -> 906.4219 | J12: =Assumptions!J16*J8 -> 1004.4503
A13: Other operating costs | C13: 1411.7 | D13: 1568.5 | E13: 1755.8 | F13: =Assumptions!F17*F8 -> 1898.852 | G13: =Assumptions!G17*G8 -> 2106.1985 | H13: =Assumptions!H17*H8 -> 2335.4482 | I13: =Assumptions!I17*I8 -> 2592.3666 | J13: =Assumptions!J17*J8 -> 2852.6387
A14: Total restaurant operating costs | C14: =SUM(C10:C13) -> 7285.3 | D14: =SUM(D10:D13) -> 8296.2 | E14: =SUM(E10:E13) -> 8899.4 | F14: =SUM(F10:F13) -> 9729.9794 | G14: =SUM(G10:G13) -> 10794.268 | H14: =SUM(H10:H13) -> 11987.545 | I14: =SUM(I10:I13) -> 13270.017 | J14: =SUM(J10:J13) -> 14664.974
A15: Restaurant-level operating profit | C15: =C8-C14 -> 2586.4 | D15: =D8-D14 -> 3017.7 | E15: =E8-E14 -> 3026.2 | F15: =F8-F14 -> 3365.5514 | G15: =G8-G14 -> 3832.1112 | H15: =H8-H14 -> 4344.2603 | I15: =I8-I14 -> 4858.4214 | J15: =J8-J14 -> 5424.0314
A16: Restaurant-level margin % | C16: =C15/C8 -> 0.26200148 | D16: =D15/D8 -> 0.266725 | E16: =E15/E8 -> 0.25375662 | F16: =F15/F8 -> 0.257 | G16: =G15/G8 -> 0.262 | H16: =H15/H8 -> 0.266 | I16: =I15/I8 -> 0.268 | J16: =J15/J8 -> 0.27
A17: General & administrative | C17: 633.6 | D17: 697.5 | E17: 652 | F17: =Assumptions!F19*F8 -> 707.15867 | G17: =Assumptions!G19*G8 -> 775.19807 | H17: =Assumptions!H19*H8 -> 849.2539 | I17: =Assumptions!I19*I8 -> 924.55034 | J17: =Assumptions!J19*J8 -> 1024.5393
A18: Depreciation & amortization | C18: 319.4 | D18: 335 | E18: 361.4 | F18: =Assumptions!F20*F8 -> 405.96146 | G18: =Assumptions!G20*G8 -> 453.41774 | H18: =Assumptions!H20*H8 -> 506.28598 | I18: =Assumptions!I20*I8 -> 561.98158 | J18: =Assumptions!J20*J8 -> 622.75916
A19: Pre-opening costs | C19: 44.5 | D19: 41.9 | E19: 49.5 | F19: =Assumptions!F21*F8 -> 52.382123 | G19: =Assumptions!G21*G8 -> 58.505515 | H19: =Assumptions!H21*H8 -> 65.327223 | I19: =Assumptions!I21*I8 -> 72.513752 | J19: =Assumptions!J21*J8 -> 80.356021
A20: Impairment, closure & asset disposals | C20: 30.8 | D20: 26.9 | E20: 27.5 | F20: =Assumptions!F22*F8 -> 26.191062 | G20: =Assumptions!G22*G8 -> 29.252758 | H20: =Assumptions!H22*H8 -> 32.663612 | I20: =Assumptions!I22*I8 -> 36.256876 | J20: =Assumptions!J22*J8 -> 40.17801
A21: Total operating expenses | C21: =C14+C17+C18+C19+C20 -> 8313.6 | D21: =D14+D17+D18+D19+D20 -> 9397.5 | E21: =E14+E17+E18+E19+E20 -> 9989.8 | F21: =F14+F17+F18+F19+F20 -> 10921.673 | G21: =G14+G17+G18+G19+G20 -> 12110.642 | H21: =H14+H17+H18+H19+H20 -> 13441.076 | I21: =I14+I17+I18+I19+I20 -> 14865.319 | J21: =J14+J17+J18+J19+J20 -> 16432.806
A22: Income from operations (EBIT) | C22: =C8-C21 -> 1558.1 | D22: =D8-D21 -> 1916.4 | E22: =E8-E21 -> 1935.8 | F22: =F8-F21 -> 2173.8581 | G22: =G8-G21 -> 2515.7371 | H22: =H8-H21 -> 2890.7296 | I22: =I8-I21 -> 3263.1188 | J22: =J8-J21 -> 3656.1989
A23: Operating margin % | C23: =C22/C8 -> 0.15783502 | D23: =D22/D8 -> 0.16938456 | E23: =E22/E8 -> 0.16232307 | F23: =F22/F8 -> 0.166 | G23: =G22/G8 -> 0.172 | H23: =H22/H8 -> 0.177 | I23: =I22/I8 -> 0.18 | J23: =J22/J8 -> 0.182
A24: Interest & other income, net | C24: 63.1 | D24: 93.6 | E24: 73.8 | F24: =Assumptions!F26*('Balance Sheet'!E5+'Balance Sheet'!E6+'Balance Sheet'!E12) -> 43.6205 | G24: =Assumptions!G26*('Balance Sheet'!F5+'Balance Sheet'!F6+'Balance Sheet'!F12) -> 54.287765 | H24: =Assumptions!H26*('Balance Sheet'!G5+'Balance Sheet'!G6+'Balance Sheet'!G12) -> 66.696282 | I24: =Assumptions!I26*('Balance Sheet'!H5+'Balance Sheet'!H6+'Balance Sheet'!H12) -> 81.064611 | J24: =Assumptions!J26*('Balance Sheet'!I5+'Balance Sheet'!I6+'Balance Sheet'!I12) -> 97.248714
A25: Pretax income | C25: =C22+C24 -> 1621.2 | D25: =D22+D24 -> 2010 | E25: =E22+E24 -> 2009.6 | F25: =F22+F24 -> 2217.4786 | G25: =G22+G24 -> 2570.0249 | H25: =H22+H24 -> 2957.4259 | I25: =I22+I24 -> 3344.1834 | J25: =J22+J24 -> 3753.4477
A26: Income taxes | C26: 391.8 | D26: 476.1 | E26: 473.8 | F26: =Assumptions!F27*F25 -> 532.19487 | G26: =Assumptions!G27*G25 -> 616.80598 | H26: =Assumptions!H27*H25 -> 709.78222 | I26: =Assumptions!I27*I25 -> 802.60403 | J26: =Assumptions!J27*J25 -> 900.82744
A27: Net income | C27: =C25-C26 -> 1229.4 | D27: =D25-D26 -> 1533.9 | E27: =E25-E26 -> 1535.8 | F27: =F25-F26 -> 1685.2838 | G27: =G25-G26 -> 1953.2189 | H27: =H25-H26 -> 2247.6437 | I27: =I25-I26 -> 2541.5794 | J27: =J25-J26 -> 2852.6202
A28: Net margin % | C28: =C27/C8 -> 0.12453782 | D28: =D27/D8 -> 0.13557659 | E28: =E27/E8 -> 0.12878178 | F28: =F27/F8 -> 0.12869152 | G28: =G27/G8 -> 0.13354084 | H28: =H27/H8 -> 0.13762371 | I28: =I27/I8 -> 0.14019848 | J28: =J27/J8 -> 0.14199908
A30: Diluted shares outstanding (mm) | C30: 1386 | D30: 1377 | E30: 1343 | F30: =('Cash Flow'!F27+'Cash Flow'!F29)/2 -> 1280.0407 | G30: =('Cash Flow'!G27+'Cash Flow'!G29)/2 -> 1236.864 | H30: =('Cash Flow'!H27+'Cash Flow'!H29)/2 -> 1186.7623 | I30: =('Cash Flow'!I27+'Cash Flow'!I29)/2 -> 1129.5962 | J30: =('Cash Flow'!J27+'Cash Flow'!J29)/2 -> 1065.1621
A31: Diluted EPS | C31: =C27/C30 -> 0.88701299 | D31: =D27/D30 -> 1.1139434 | E31: =E27/E30 -> 1.1435592 | F31: =F27/F30 -> 1.3165861 | G31: =G27/G30 -> 1.5791704 | H31: =H27/H30 -> 1.8939291 | I31: =I27/I30 -> 2.2499894 | J31: =J27/J30 -> 2.678109
A32: Memo: EBITDA | C32: =C22+C18 -> 1877.5 | D32: =D22+D18 -> 2251.4 | E32: =E22+E18 -> 2297.2 | F32: =F22+F18 -> 2579.8196 | G32: =G22+G18 -> 2969.1549 | H32: =H22+H18 -> 3397.0156 | I32: =I22+I18 -> 3825.1004 | J32: =J22+J18 -> 4278.9581

Sheet Balance Sheet
A1: Chipotle Mexican Grill: Consolidated Balance Sheet
A2: $ in millions; FY2023-25 reported, FY2026E-30E projected
A4: Assets | C4: FY2023 | D4: FY2024 | E4: FY2025 | F4: FY2026E | G4: FY2027E | H4: FY2028E | I4: FY2029E | J4: FY2030E
A5: Cash & cash equivalents | C5: 560.6 | D5: 748.5 | E5: 350.6 | F5: ='Cash Flow'!F21 -> 655.37901 | G5: ='Cash Flow'!G21 -> 1009.9081 | H5: ='Cash Flow'!H21 -> 1420.4317 | I5: ='Cash Flow'!I21 -> 1882.8347 | J5: ='Cash Flow'!J21 -> 2404.3398
A6: Short-term investments | C6: 734.8 | D6: 674.4 | E6: 698.6 | F6: =E6 -> 698.6 | G6: =F6 -> 698.6 | H6: =G6 -> 698.6 | I6: =H6 -> 698.6 | J6: =I6 -> 698.6
A7: Accounts receivable | C7: 115.5 | D7: 144 | E7: 156.5 | F7: =Assumptions!F34*'Income Statement'!F8 -> 171.55145 | G7: =Assumptions!G34*'Income Statement'!G8 -> 191.60556 | H7: =Assumptions!H34*'Income Statement'!H8 -> 213.94666 | I7: =Assumptions!I34*'Income Statement'!I8 -> 237.48254 | J7: =Assumptions!J34*'Income Statement'!J8 -> 263.16597
A8: Inventory | C8: 39.3 | D8: 48.9 | E8: 49.5 | F8: =Assumptions!F35*'Income Statement'!F8 -> 54.346453 | G8: =Assumptions!G35*'Income Statement'!G8 -> 60.699472 | H8: =Assumptions!H35*'Income Statement'!H8 -> 67.776994 | I8: =Assumptions!I35*'Income Statement'!I8 -> 75.233018 | J8: =Assumptions!J35*'Income Statement'!J8 -> 83.369371
A9: Prepaid expenses & other current assets | C9: 170.4 | D9: 164.8 | E9: 211.8 | F9: =Assumptions!F36*'Income Statement'!F8 -> 233.10045 | G9: =Assumptions!G36*'Income Statement'!G8 -> 260.34954 | H9: =Assumptions!H36*'Income Statement'!H8 -> 290.70614 | I9: =Assumptions!I36*'Income Statement'!I8 -> 322.6862 | J9: =Assumptions!J36*'Income Statement'!J8 -> 357.58429
A10: Total current assets | C10: =SUM(C5:C9) -> 1620.6 | D10: =SUM(D5:D9) -> 1780.6 | E10: =SUM(E5:E9) -> 1467 | F10: =SUM(F5:F9) -> 1812.9774 | G10: =SUM(G5:G9) -> 2221.1626 | H10: =SUM(H5:H9) -> 2691.4615 | I10: =SUM(I5:I9) -> 3216.8364 | J10: =SUM(J5:J9) -> 3807.0594
A11: Property, equipment & lease assets, net | C11: 5749 | D11: 6390 | E11: 7142 | F11: =E11+Assumptions!F28*'Income Statement'!F8-'Income Statement'!F18+((F20+F22)-(E20+E22)) -> 7967.4462 | G11: =F11+Assumptions!G28*'Income Statement'!G8-'Income Statement'!G18+((G20+G22)-(F20+F22)) -> 8984.6345 | H11: =G11+Assumptions!H28*'Income Statement'!H8-'Income Statement'!H18+((H20+H22)-(G20+G22)) -> 10102.428 | I11: =H11+Assumptions!I28*'Income Statement'!I8-'Income Statement'!I18+((I20+I22)-(H20+H22)) -> 11302.157 | J11: =I11+Assumptions!J28*'Income Statement'!J8-'Income Statement'!J18+((J20+J22)-(I20+I22)) -> 12598.621
A12: Long-term investments | C12: 564.5 | D12: 868 | E12: 197.1 | F12: =E12 -> 197.1 | G12: =F12 -> 197.1 | H12: =G12 -> 197.1 | I12: =H12 -> 197.1 | J12: =I12 -> 197.1
A13: Goodwill & intangible assets | C13: 21.9 | D13: 21.9 | E13: 21.9 | F13: =E13 -> 21.9 | G13: =F13 -> 21.9 | H13: =G13 -> 21.9 | I13: =H13 -> 21.9 | J13: =I13 -> 21.9
A14: Other long-term assets | C14: 88.7 | D14: 144.6 | E14: 166.6 | F14: =E14 -> 166.6 | G14: =F14 -> 166.6 | H14: =G14 -> 166.6 | I14: =H14 -> 166.6 | J14: =I14 -> 166.6
A15: Total assets | C15: =C10+C11+C12+C13+C14 -> 8044.7 | D15: =D10+D11+D12+D13+D14 -> 9205.1 | E15: =E10+E11+E12+E13+E14 -> 8994.6 | F15: =F10+F11+F12+F13+F14 -> 10166.024 | G15: =G10+G11+G12+G13+G14 -> 11591.397 | H15: =H10+H11+H12+H13+H14 -> 13179.489 | I15: =I10+I11+I12+I13+I14 -> 14904.593 | J15: =J10+J11+J12+J13+J14 -> 16791.281
A16: Liabilities & Equity
A17: Accounts payable | C17: 197.7 | D17: 210.7 | E17: 212.8 | F17: =Assumptions!F37*'Income Statement'!F8 -> 233.10045 | G17: =Assumptions!G37*'Income Statement'!G8 -> 260.34954 | H17: =Assumptions!H37*'Income Statement'!H8 -> 290.70614 | I17: =Assumptions!I37*'Income Statement'!I8 -> 322.6862 | J17: =Assumptions!J37*'Income Statement'!J8 -> 357.58429
A18: Accrued & other current liabilities | C18: 375.2 | D18: 441.7 | E18: 432.6 | F18: =Assumptions!F38*'Income Statement'!F8 -> 475.36777 | G18: =Assumptions!G38*'Income Statement'!G8 -> 530.93755 | H18: =Assumptions!H38*'Income Statement'!H8 -> 592.84455 | I18: =Assumptions!I38*'Income Statement'!I8 -> 658.0623 | J18: =Assumptions!J38*'Income Statement'!J8 -> 729.23089
A19: Unearned revenue | C19: 209.7 | D19: 238.6 | E19: 240.4 | F19: =Assumptions!F39*'Income Statement'!F8 -> 264.52972 | G19: =Assumptions!G39*'Income Statement'!G8 -> 295.45285 | H19: =Assumptions!H39*'Income Statement'!H8 -> 329.90248 | I19: =Assumptions!I39*'Income Statement'!I8 -> 366.19445 | J19: =Assumptions!J39*'Income Statement'!J8 -> 405.7979
A20: Current portion of lease liabilities | C20: 248.1 | D20: 277.8 | E20: 302.4 | F20: =Assumptions!F40*'Income Statement'!F8 -> 332.62648 | G20: =Assumptions!G40*'Income Statement'!G8 -> 371.51002 | H20: =Assumptions!H40*'Income Statement'!H8 -> 414.82787 | I20: =Assumptions!I40*'Income Statement'!I8 -> 460.46232 | J20: =Assumptions!J40*'Income Statement'!J8 -> 510.26073
A21: Total current liabilities | C21: =SUM(C17:C20) -> 1030.7 | D21: =SUM(D17:D20) -> 1168.8 | E21: =SUM(E17:E20) -> 1188.2 | F21: =SUM(F17:F20) -> 1305.6244 | G21: =SUM(G17:G20) -> 1458.25 | H21: =SUM(H17:H20) -> 1628.281 | I21: =SUM(I17:I20) -> 1807.4053 | J21: =SUM(J17:J20) -> 2002.8738
A22: Long-term lease liabilities | C22: 3804 | D22: 4263 | E22: 4773 | F22: =Assumptions!F41*'Income Statement'!F8 -> 5240.8314 | G22: =Assumptions!G41*'Income Statement'!G8 -> 5853.4768 | H22: =Assumptions!H41*'Income Statement'!H8 -> 6535.9887 | I22: =Assumptions!I41*'Income Statement'!I8 -> 7255.0009 | J22: =Assumptions!J41*'Income Statement'!J8 -> 8039.6199
A23: Other long-term liabilities | C23: 148 | D23: 117.3 | E23: 202.4 | F23: =E23 -> 202.4 | G23: =F23 -> 202.4 | H23: =G23 -> 202.4 | I23: =H23 -> 202.4 | J23: =I23 -> 202.4
A24: Total liabilities | C24: =C21+C22+C23 -> 4982.7 | D24: =D21+D22+D23 -> 5549.1 | E24: =E21+E22+E23 -> 6163.6 | F24: =F21+F22+F23 -> 6748.8559 | G24: =G21+G22+G23 -> 7514.1267 | H24: =H21+H22+H23 -> 8366.6697 | I24: =I21+I22+I23 -> 9264.8062 | J24: =J21+J22+J23 -> 10244.894
A25: Total shareholders' equity | C25: 3062 | D25: 3656 | E25: 2831 | F25: =E25+'Income Statement'!F27+Assumptions!F29-'Cash Flow'!F24 -> 3417.1677 | G25: =F25+'Income Statement'!G27+Assumptions!G29-'Cash Flow'!G24 -> 4077.2704 | H25: =G25+'Income Statement'!H27+Assumptions!H29-'Cash Flow'!H24 -> 4812.8194 | I25: =H25+'Income Statement'!I27+Assumptions!I29-'Cash Flow'!I24 -> 5639.7871 | J25: =I25+'Income Statement'!J27+Assumptions!J29-'Cash Flow'!J24 -> 6546.387
A26: Total liabilities & equity | C26: =C24+C25 -> 8044.7 | D26: =D24+D25 -> 9205.1 | E26: =E24+E25 -> 8994.6 | F26: =F24+F25 -> 10166.024 | G26: =G24+G25 -> 11591.397 | H26: =H24+H25 -> 13179.489 | I26: =I24+I25 -> 14904.593 | J26: =J24+J25 -> 16791.281
A27: Balance check (Assets − L&E) | C27: =C15-C26 -> 0 | D27: =D15-D26 -> 0 | E27: =E15-E26 -> 0 | F27: =F15-F26 -> 0 | G27: =G15-G26 -> 0 | H27: =H15-H26 -> 0 | I27: =I15-I26 -> 0 | J27: =J15-J26 -> 0
A29: Memo: Net cash (ex-leases) = cash + investments | C29: =C5+C6+C12 -> 1859.9 | D29: =D5+D6+D12 -> 2290.9 | E29: =E5+E6+E12 -> 1246.3 | F29: =F5+F6+F12 -> 1551.079 | G29: =G5+G6+G12 -> 1905.6081 | H29: =H5+H6+H12 -> 2316.1317 | I29: =I5+I6+I12 -> 2778.5347 | J29: =J5+J6+J12 -> 3300.0398

Sheet Cash Flow
A1: Chipotle Mexican Grill: Cash Flow Statement (projected)
A2: $ in millions; FY2026E-30E. Built to articulate with the income statement & balance sheet.
C4: FY2023 | D4: FY2024 | E4: FY2025 | F4: FY2026E | G4: FY2027E | H4: FY2028E | I4: FY2029E | J4: FY2030E
A5: Net income | C5: ='Income Statement'!C27 -> 1229.4 | D5: ='Income Statement'!D27 -> 1533.9 | E5: ='Income Statement'!E27 -> 1535.8 | F5: ='Income Statement'!F27 -> 1685.2838 | G5: ='Income Statement'!G27 -> 1953.2189 | H5: ='Income Statement'!H27 -> 2247.6437 | I5: ='Income Statement'!I27 -> 2541.5794 | J5: ='Income Statement'!J27 -> 2852.6202
A6: Depreciation & amortization | C6: ='Income Statement'!C18 -> 319.4 | D6: ='Income Statement'!D18 -> 335 | E6: ='Income Statement'!E18 -> 361.4 | F6: ='Income Statement'!F18 -> 405.96146 | G6: ='Income Statement'!G18 -> 453.41774 | H6: ='Income Statement'!H18 -> 506.28598 | I6: ='Income Statement'!I18 -> 561.98158 | J6: ='Income Statement'!J18 -> 622.75916
A7: Stock-based compensation | C7: =Assumptions!C29 -> 124 | D7: =Assumptions!D29 -> 131.7 | E7: =Assumptions!E29 -> 119.5 | F7: =Assumptions!F29 -> 120 | G7: =Assumptions!G29 -> 125 | H7: =Assumptions!H29 -> 130 | I7: =Assumptions!I29 -> 135 | J7: =Assumptions!J29 -> 140
A8: Δ Accounts receivable | F8: ='Balance Sheet'!E7-'Balance Sheet'!F7 -> -15.051454 | G8: ='Balance Sheet'!F7-'Balance Sheet'!G7 -> -20.054108 | H8: ='Balance Sheet'!G7-'Balance Sheet'!H7 -> -22.341094 | I8: ='Balance Sheet'!H7-'Balance Sheet'!I7 -> -23.535882 | J8: ='Balance Sheet'!I7-'Balance Sheet'!J7 -> -25.68343
A9: Δ Inventory | F9: ='Balance Sheet'!E8-'Balance Sheet'!F8 -> -4.846453 | G9: ='Balance Sheet'!F8-'Balance Sheet'!G8 -> -6.3530189 | H9: ='Balance Sheet'!G8-'Balance Sheet'!H8 -> -7.0775223 | I9: ='Balance Sheet'!H8-'Balance Sheet'!I8 -> -7.4560235 | J9: ='Balance Sheet'!I8-'Balance Sheet'!J8 -> -8.1363538
A10: Δ Prepaid & other CA | F10: ='Balance Sheet'!E9-'Balance Sheet'!F9 -> -21.300449 | G10: ='Balance Sheet'!F9-'Balance Sheet'!G9 -> -27.249093 | H10: ='Balance Sheet'!G9-'Balance Sheet'!H9 -> -30.356602 | I10: ='Balance Sheet'!H9-'Balance Sheet'!I9 -> -31.980053 | J10: ='Balance Sheet'!I9-'Balance Sheet'!J9 -> -34.898096
A11: Δ Accounts payable | F11: ='Balance Sheet'!F17-'Balance Sheet'!E17 -> 20.300449 | G11: ='Balance Sheet'!G17-'Balance Sheet'!F17 -> 27.249093 | H11: ='Balance Sheet'!H17-'Balance Sheet'!G17 -> 30.356602 | I11: ='Balance Sheet'!I17-'Balance Sheet'!H17 -> 31.980053 | J11: ='Balance Sheet'!J17-'Balance Sheet'!I17 -> 34.898096
A12: Δ Accrued & other CL | F12: ='Balance Sheet'!F18-'Balance Sheet'!E18 -> 42.767769 | G12: ='Balance Sheet'!G18-'Balance Sheet'!F18 -> 55.56978 | H12: ='Balance Sheet'!H18-'Balance Sheet'!G18 -> 61.907002 | I12: ='Balance Sheet'!I18-'Balance Sheet'!H18 -> 65.217748 | J12: ='Balance Sheet'!J18-'Balance Sheet'!I18 -> 71.168589
A13: Δ Unearned revenue | F13: ='Balance Sheet'!F19-'Balance Sheet'!E19 -> 24.129723 | G13: ='Balance Sheet'!G19-'Balance Sheet'!F19 -> 30.923128 | H13: ='Balance Sheet'!H19-'Balance Sheet'!G19 -> 34.449626 | I13: ='Balance Sheet'!I19-'Balance Sheet'!H19 -> 36.29197 | J13: ='Balance Sheet'!J19-'Balance Sheet'!I19 -> 39.603457
A14: Cash from operations | F14: =SUM(F5:F13) -> 2257.2448 | G14: =SUM(G5:G13) -> 2591.7225 | H14: =SUM(H5:H13) -> 2950.8677 | I14: =SUM(I5:I13) -> 3309.0788 | J14: =SUM(J5:J13) -> 3692.3316
A15: Capital expenditures | F15: =-Assumptions!F28*'Income Statement'!F8 -> -733.34973 | G15: =-Assumptions!G28*'Income Statement'!G8 -> -819.07721 | H15: =-Assumptions!H28*'Income Statement'!H8 -> -898.24932 | I15: =-Assumptions!I28*'Income Statement'!I8 -> -997.06409 | J15: =-Assumptions!J28*'Income Statement'!J8 -> -1084.8063
A16: Cash from investing | F16: =F15 -> -733.34973 | G16: =G15 -> -819.07721 | H16: =H15 -> -898.24932 | I16: =I15 -> -997.06409 | J16: =J15 -> -1084.8063
A17: Share repurchases | F17: =-Assumptions!F30*(F14+F15) -> -1219.1161 | G17: =-Assumptions!G30*(G14+G15) -> -1418.1162 | H17: =-Assumptions!H30*(H14+H15) -> -1642.0947 | I17: =-Assumptions!I30*(I14+I15) -> -1849.6118 | J17: =-Assumptions!J30*(J14+J15) -> -2086.0203
A18: Cash from financing | F18: =F17 -> -1219.1161 | G18: =G17 -> -1418.1162 | H18: =H17 -> -1642.0947 | I18: =I17 -> -1849.6118 | J18: =J17 -> -2086.0203
A19: Net change in cash | F19: =F14+F16+F18 -> 304.77901 | G19: =G14+G16+G18 -> 354.52905 | H19: =H14+H16+H18 -> 410.52367 | I19: =I14+I16+I18 -> 462.40294 | J19: =J14+J16+J18 -> 521.50507
A20: Beginning cash | F20: ='Balance Sheet'!E5 -> 350.6 | G20: ='Balance Sheet'!F5 -> 655.37901 | H20: ='Balance Sheet'!G5 -> 1009.9081 | I20: ='Balance Sheet'!H5 -> 1420.4317 | J20: ='Balance Sheet'!I5 -> 1882.8347
A21: Ending cash | F21: =F20+F19 -> 655.37901 | G21: =G20+G19 -> 1009.9081 | H21: =H20+H19 -> 1420.4317 | I21: =I20+I19 -> 1882.8347 | J21: =J20+J19 -> 2404.3398
A23: Memo: Free cash flow (CFO − capex) | F23: =F14+F15 -> 1523.8951 | G23: =G14+G15 -> 1772.6452 | H23: =H14+H15 -> 2052.6184 | I23: =I14+I15 -> 2312.0147 | J23: =J14+J15 -> 2607.5254
A24: Memo: Buyback $ (positive) | F24: =-F17 -> 1219.1161 | G24: =-G17 -> 1418.1162 | H24: =-H17 -> 1642.0947 | I24: =-I17 -> 1849.6118 | J24: =-J17 -> 2086.0203
A26: SHARE COUNT SCHEDULE (mm)
A27: Diluted shares, beginning | F27: 1300 | G27: =F29 -> 1260.0813 | H27: =G29 -> 1213.6466 | I27: =H29 -> 1159.878 | J27: =I29 -> 1099.3144
A28: Shares repurchased | F28: =F24/Assumptions!F31 -> 39.918666 | G28: =G24/Assumptions!G31 -> 46.434715 | H28: =H24/Assumptions!H31 -> 53.768654 | I28: =I24/Assumptions!I31 -> 60.563581 | J28: =J24/Assumptions!J31 -> 68.304528
A29: Diluted shares, ending | F29: =F27-F28 -> 1260.0813 | G29: =G27-G28 -> 1213.6466 | H29: =H27-H28 -> 1159.878 | I29: =I27-I28 -> 1099.3144 | J29: =J27-J28 -> 1031.0099

Sheet DCF
B1: Chipotle Mexican Grill: Discounted Cash Flow
B2: $ in millions except per share. Leases treated as operating (excluded from net debt & FCF).
B3: WACC BUILD
B4: Risk-free rate (10Y UST, Jun 2026) | C4: 0.0448
B5: Equity risk premium | C5: 0.05
B6: Beta (5Y) | C6: 0.98
B7: Cost of equity | C7: =C4+C6*C5 -> 0.0938
B8: Pre-tax cost of debt | C8: 0.05
B9: Tax rate | C9: 0.24
B10: After-tax cost of debt | C10: =C8*(1-C9) -> 0.038
B11: Equity weight | C11: 1
B12: Debt weight | C12: 0
B13: WACC | C13: =C11*C7+C12*C10 -> 0.0938
B15: UNLEVERED FREE CASH FLOW | F15: FY2026E | G15: FY2027E | H15: FY2028E | I15: FY2029E | J15: FY2030E
B16: EBIT | F16: ='Income Statement'!F22 -> 2173.8581 | G16: ='Income Statement'!G22 -> 2515.7371 | H16: ='Income Statement'!H22 -> 2890.7296 | I16: ='Income Statement'!I22 -> 3263.1188 | J16: ='Income Statement'!J22 -> 3656.1989
B17: Less: taxes on EBIT | F17: =-F16*$C$9 -> -521.72595 | G17: =-G16*$C$9 -> -603.77692 | H17: =-H16*$C$9 -> -693.77511 | I17: =-I16*$C$9 -> -783.14852 | J17: =-J16*$C$9 -> -877.48775
B18: NOPAT | F18: =F16+F17 -> 1652.1322 | G18: =G16+G17 -> 1911.9602 | H18: =H16+H17 -> 2196.9545 | I18: =I16+I17 -> 2479.9703 | J18: =J16+J17 -> 2778.7112
B19: Plus: D&A | F19: ='Income Statement'!F18 -> 405.96146 | G19: ='Income Statement'!G18 -> 453.41774 | H19: ='Income Statement'!H18 -> 506.28598 | I19: ='Income Statement'!I18 -> 561.98158 | J19: ='Income Statement'!J18 -> 622.75916
B20: Less: capital expenditures | F20: =-Assumptions!F28*'Income Statement'!F8 -> -733.34973 | G20: =-Assumptions!G28*'Income Statement'!G8 -> -819.07721 | H20: =-Assumptions!H28*'Income Statement'!H8 -> -898.24932 | I20: =-Assumptions!I28*'Income Statement'!I8 -> -997.06409 | J20: =-Assumptions!J28*'Income Statement'!J8 -> -1084.8063
B21: Less: change in net working capital | F21: ='Cash Flow'!F8+'Cash Flow'!F9+'Cash Flow'!F10+'Cash Flow'!F11+'Cash Flow'!F12+'Cash Flow'!F13 -> 45.999585 | G21: ='Cash Flow'!G8+'Cash Flow'!G9+'Cash Flow'!G10+'Cash Flow'!G11+'Cash Flow'!G12+'Cash Flow'!G13 -> 60.085781 | H21: ='Cash Flow'!H8+'Cash Flow'!H9+'Cash Flow'!H10+'Cash Flow'!H11+'Cash Flow'!H12+'Cash Flow'!H13 -> 66.938012 | I21: ='Cash Flow'!I8+'Cash Flow'!I9+'Cash Flow'!I10+'Cash Flow'!I11+'Cash Flow'!I12+'Cash Flow'!I13 -> 70.517813 | J21: ='Cash Flow'!J8+'Cash Flow'!J9+'Cash Flow'!J10+'Cash Flow'!J11+'Cash Flow'!J12+'Cash Flow'!J13 -> 76.952262
B22: Unlevered free cash flow | F22: =F18+F19+F20+F21 -> 1370.7435 | G22: =G18+G19+G20+G21 -> 1606.3865 | H22: =H18+H19+H20+H21 -> 1871.9292 | I22: =I18+I19+I20+I21 -> 2115.4056 | J22: =J18+J19+J20+J21 -> 2393.6163
B23: Discount period (mid-year) | F23: 0.5 | G23: 1.5 | H23: 2.5 | I23: 3.5 | J23: 4.5
B24: Discount factor | F24: =1/(1+$C$13)^F23 -> 0.95616103 | G24: =1/(1+$C$13)^G23 -> 0.87416441 | H24: =1/(1+$C$13)^H23 -> 0.7991995 | I24: =1/(1+$C$13)^I23 -> 0.73066328 | J24: =1/(1+$C$13)^J23 -> 0.66800446
B25: PV of free cash flow | F25: =F22*F24 -> 1310.6515 | G25: =G22*G24 -> 1404.2459 | H25: =H22*H24 -> 1496.0449 | I25: =I22*I24 -> 1545.6492 | J25: =J22*J24 -> 1598.9464
B27: Sum PV of FCF (FY26-30) | C27: =SUM(F25:J25) -> 7355.5379
B28: TERMINAL VALUE: Gordon growth
B29: Terminal growth rate | C29: 0.03
B30: Terminal-year FCF (FY2030 × (1+g)) | C30: =J22*(1+C29) -> 2465.4248
B31: Terminal value | C31: =C30/($C$13-C29) -> 38643.022
B32: PV of terminal value | C32: =C31/(1+$C$13)^5 -> 24682.065
B33: Enterprise value (Gordon) | C33: =C27+C32 -> 32037.603
B34: TERMINAL VALUE: Exit multiple
B35: Exit EV/EBITDA multiple | C35: 18
B36: Terminal EBITDA (FY2030) | C36: ='Income Statement'!J32 -> 4278.9581
B37: Terminal value (exit) | C37: =C35*C36 -> 77021.246
B38: PV of terminal value (exit) | C38: =C37/(1+$C$13)^5 -> 49194.998
B39: Enterprise value (exit) | C39: =C27+C38 -> 56550.536
B41: EQUITY VALUE & PRICE
B42: Plus: net cash (ex-leases, FY2025) | C42: ='Balance Sheet'!E5+'Balance Sheet'!E6+'Balance Sheet'!E12 -> 1246.3
B43: Diluted shares (mm) | C43: 1280
...

Sheet Comps
A1: Comparable Companies: Fast-Casual / Restaurant Growth
A2: Market data ≈ Jun 2026 (stockanalysis.com / S&P Global). LTM figures. $ in millions.
A4: Company | B4: Ticker | C4: Price | D4: Mkt cap | E4: EV | F4: EBITDA(LTM) | G4: EV/EBITDA | H4: EPS(LTM) | I4: P/E | J4: Fwd P/E | K4: Rev gr 3Y
A5: Chipotle (target) | B5: CMG | C5: 30.54 | D5: 39170 | E5: 43550 | F5: ='Income Statement'!E32 -> 2297.2 | G5: =E5/F5 -> 18.957862 | H5: 1.09 | I5: 28 | J5: 25.6 | K5: 0.101
A6: CAVA Group | B6: CAVA | C6: 88.88 | D6: 10350 | E6: 10690 | F6: 149.1 | G6: 71.7 | H6: 0.52 | I6: 171.2 | J6: 145.5 | K6: 0.23
A7: Wingstop | B7: WING | C7: 161.78 | D7: 4410 | E7: 5550 | F7: 224.6 | G7: 24.7 | H7: 4.01 | I7: 40.3 | J7: 34.2 | K7: 0.135
A8: Shake Shack | B8: SHAK | C8: n/a | D8: n/a | E8: n/a | F8: n/a | G8: 18.3 | H8: n/a | I8: n/a | J8: 47.9 | K8: n/a
A9: Texas Roadhouse | B9: TXRH | C9: 177.75 | D9: 11680 | E9: 12520 | F9: 701.4 | G9: 17.9 | H9: 6.27 | I9: 28.4 | J9: 26.5 | K9: 0.096
A10: Sweetgreen | B10: SG | C10: 9.04 | D10: 1070 | E10: 1280 | F10: n/a | G10: n/a | H10: 0.14 | I10: 64.7 | J10: n/a | K10: 0.074
A12: Peer median (ex-CMG) | G12: =MEDIAN(G6,G7,G8,G9) -> 21.5 | I12: =MEDIAN(I6,I7,I9) -> 40.3 | J12: =MEDIAN(J7,J9) -> 30.35
A13: Peer mean (ex-CMG, ex-CAVA) | G13: =AVERAGE(G7,G8,G9) -> 20.3
A15: IMPLIED VALUATION (EV/EBITDA method)
A16: CMG EBITDA, LTM (FY2025) | C16: ='Income Statement'!E32 -> 2297.2
A17: Applied multiple (peer median) | C17: =G12 -> 21.5
A18: Implied enterprise value | C18: =C16*C17 -> 49389.8
A19: Plus: net cash (ex-leases) | C19: ='Balance Sheet'!E29 -> 1246.3
A20: Implied equity value | C20: =C18+C19 -> 50636.1
A21: Diluted shares (mm) | C21: 1280
A22: Implied price per share | C22: =C20/C21 -> 39.559453
A23: Current price | C23: 30.54
A24: Upside / (downside) | C24: =C22/C23-1 -> 0.29533245
A26: Cross-check: P/E method
A27: CMG FY2026E EPS | C27: ='Income Statement'!F31 -> 1.3165861
A28: Applied fwd P/E (peer median) | C28: =J12 -> 30.35
A29: Implied price per share | C29: =C27*C28 -> 39.958388
A31: CAVA trades at ~72x EV/EBITDA (high-growth outlier); median used to avoid distortion.
